{
  "overall_score": 0.0,
  "error": "{'target_service': 'generative_ai_inference', 'status': 500, 'code': None, 'opc-request-id': 'ED9C72BE2DBA4DCFA73396B5D182F4D5/5A1977C6D2266AEB37B4454B45D45755/6E83E363543098910E4093A98B90416C', 'message': 'Internal Server Error', 'operation_name': 'chat', 'timestamp': '2025-07-30T20:59:40.021472+00:00', 'client_version': 'Oracle-PythonSDK/2.141.1', 'request_endpoint': 'POST https://inference.generativeai.us-chicago-1.oci.oraclecloud.com/20231130/actions/chat', 'logging_tips': 'To get more info on the failing request, refer to https://docs.oracle.com/en-us/iaas/tools/python/latest/logging.html for ways to log the request/response details.', 'troubleshooting_tips': \"See https://docs.oracle.com/iaas/Content/API/References/apierrors.htm#apierrors_500__500_none for more information about resolving this error. Also see https://docs.oracle.com/iaas/api/#/en/generative-ai-inference/20231130/ChatResult/Chat for details on this operation's requirements. If you are unable to resolve this generative_ai_inference issue, please contact Oracle support and provide them this full error message.\"}",
  "metrics": {
    "api_response_time": 0.3612802028656006,
    "total_response_time": 0.3612802028656006,
    "input_tokens": 0,
    "output_tokens": 0,
    "total_tokens": 0,
    "tokens_per_second": 0,
    "model_id": "ocid1.generativeaimodel.oc1.us-chicago-1.amaaaaaask7dceya3bsfz4ogiuv3yc7gcnlry7gi3zzx6tnikg6jltqszm2q",
    "timestamp": "2025-07-30T20:59:40.021764"
  }
}