{
  "overall_score": 0.0,
  "error": "{'target_service': 'generative_ai_inference', 'status': 500, 'code': None, 'opc-request-id': '3C7F63A570B74BD39451788ECA7EF1A1/F712AAA19846CFE71AB9A05A90BA5B87/CF29A1B2E93A2FEEE1F29ADFB55760DF', 'message': 'Internal Server Error', 'operation_name': 'chat', 'timestamp': '2025-07-30T21:01:12.571531+00:00', 'client_version': 'Oracle-PythonSDK/2.141.1', 'request_endpoint': 'POST https://inference.generativeai.us-chicago-1.oci.oraclecloud.com/20231130/actions/chat', 'logging_tips': 'To get more info on the failing request, refer to https://docs.oracle.com/en-us/iaas/tools/python/latest/logging.html for ways to log the request/response details.', 'troubleshooting_tips': \"See https://docs.oracle.com/iaas/Content/API/References/apierrors.htm#apierrors_500__500_none for more information about resolving this error. Also see https://docs.oracle.com/iaas/api/#/en/generative-ai-inference/20231130/ChatResult/Chat for details on this operation's requirements. If you are unable to resolve this generative_ai_inference issue, please contact Oracle support and provide them this full error message.\"}",
  "metrics": {
    "api_response_time": 0.32964634895324707,
    "total_response_time": 0.32964634895324707,
    "input_tokens": 0,
    "output_tokens": 0,
    "total_tokens": 0,
    "tokens_per_second": 0,
    "model_id": "ocid1.generativeaimodel.oc1.us-chicago-1.amaaaaaask7dceya3bsfz4ogiuv3yc7gcnlry7gi3zzx6tnikg6jltqszm2q",
    "timestamp": "2025-07-30T21:01:12.571773"
  }
}